Workbook

Sheet ReadMe
A1: Resource Utilization & Cost Calculator (J&B LLC) — SAMPLE FILLED
A3: This workbook is pre-populated with example data so you can see calculations immediately.
A5: Tabs: Inputs, Resources, Scenarios, Team Summary, JR Example

Sheet Inputs
A1: Monthly Operating (Indirect) Costs ($) | B1: 30000
A2: Target Gross Margin % (e.g., 0.5 for 50%) | B2: 0.5

Sheet Resources
A1: Resource Name | B1: Type (Salaried/Hourly) | C1: Paid Hours/Week | D1: Annual All-in Cost ($) | E1: Hourly Cost ($) | F1: Weekly Cost ($) | G1: Cost per Paid Hour ($) | H1: Billable Rate ($/hr) | I1: Billed Hours/Week | J1: Revenue This Week ($) | K1: Idle Hours | L1: Idle Labor Cost ($) | M1: Overhead per Paid Hour ($) | N1: Weekly Overhead Cost ($) | O1: Total Weekly Cost ($) | P1: Profit This Week ($) | Q1: Gross Margin % | R1: Utilization (Billed/Paid) | S1: Potential Revenue @100% ($) | T1: Revenue Lost from Idle ($) | U1: Profit @100% ($) | V1: Margin @100% | W1: Rate Floor @Current Util ($/hr)
A2: Austin (Tech I) | B2: Hourly | C2: 40 | E2: 35 | F2: =IF(B2="Salaried",D2/52,E2*C2) -> 1400 | G2: =IF(C2>0,F2/C2,0) -> 35 | H2: 125 | I2: 27.5 | J2: =H2*I2 -> 3437.5 | K2: =C2-I2 -> 12.5 | L2: =K2*G2 -> 437.5 | M2: =IF(SUM(C:C)>0,(Inputs!B1*12/52)/SUM(C:C),0) -> 28.846154 | N2: =C2*M2 -> 1153.8462 | O2: =F2+N2 -> 2553.8462 | P2: =J2-O2 -> 883.65385 | Q2: =IF(J2>0,P2/J2,0) -> 0.25706294 | R2: =IF(C2>0,I2/C2,0) -> 0.6875 | S2: =H2*C2 -> 5000 | T2: =S2-J2 -> 1562.5 | U2: =S2-O2 -> 2446.1538 | V2: =IF(S2>0,U2/S2,0) -> 0.48923077 | W2: =IF(R2>0, ((G2+M2)/R2)/(1-Inputs!B2), 0) -> 185.73427
A3: Maria (PM) | B3: Salaried | C3: 40 | D3: 98800 | F3: =IF(B3="Salaried",D3/52,E3*C3) -> 1900 | G3: =IF(C3>0,F3/C3,0) -> 47.5 | H3: 150 | I3: 32 | J3: =H3*I3 -> 4800 | K3: =C3-I3 -> 8 | L3: =K3*G3 -> 380 | M3: =IF(SUM(C:C)>0,(Inputs!B1*12/52)/SUM(C:C),0) -> 28.846154 | N3: =C3*M3 -> 1153.8462 | O3: =F3+N3 -> 3053.8462 | P3: =J3-O3 -> 1746.1538 | Q3: =IF(J3>0,P3/J3,0) -> 0.36378205 | R3: =IF(C3>0,I3/C3,0) -> 0.8 | S3: =H3*C3 -> 6000 | T3: =S3-J3 -> 1200 | U3: =S3-O3 -> 2946.1538 | V3: =IF(S3>0,U3/S3,0) -> 0.49102564 | W3: =IF(R3>0, ((G3+M3)/R3)/(1-Inputs!B2), 0) -> 190.86538
A4: DeShawn (Installer) | B4: Hourly | C4: 40 | E4: 28 | F4: =IF(B4="Salaried",D4/52,E4*C4) -> 1120 | G4: =IF(C4>0,F4/C4,0) -> 28 | H4: 110 | I4: 22 | J4: =H4*I4 -> 2420 | K4: =C4-I4 -> 18 | L4: =K4*G4 -> 504 | M4: =IF(SUM(C:C)>0,(Inputs!B1*12/52)/SUM(C:C),0) -> 28.846154 | N4: =C4*M4 -> 1153.8462 | O4: =F4+N4 -> 2273.8462 | P4: =J4-O4 -> 146.15385 | Q4: =IF(J4>0,P4/J4,0) -> 0.060394151 | R4: =IF(C4>0,I4/C4,0) -> 0.55 | S4: =H4*C4 -> 4400 | T4: =S4-J4 -> 1980 | U4: =S4-O4 -> 2126.1538 | V4: =IF(S4>0,U4/S4,0) -> 0.48321678 | W4: =IF(R4>0, ((G4+M4)/R4)/(1-Inputs!B2), 0) -> 206.71329
A5: Priya (Engineer) | B5: Salaried | C5: 40 | D5: 156000 | F5: =IF(B5="Salaried",D5/52,E5*C5) -> 3000 | G5: =IF(C5>0,F5/C5,0) -> 75 | H5: 185 | I5: 34 | J5: =H5*I5 -> 6290 | K5: =C5-I5 -> 6 | L5: =K5*G5 -> 450 | M5: =IF(SUM(C:C)>0,(Inputs!B1*12/52)/SUM(C:C),0) -> 28.846154 | N5: =C5*M5 -> 1153.8462 | O5: =F5+N5 -> 4153.8462 | P5: =J5-O5 -> 2136.1538 | Q5: =IF(J5>0,P5/J5,0) -> 0.3396111 | R5: =IF(C5>0,I5/C5,0) -> 0.85 | S5: =H5*C5 -> 7400 | T5: =S5-J5 -> 1110 | U5: =S5-O5 -> 3246.1538 | V5: =IF(S5>0,U5/S5,0) -> 0.43866944 | W5: =IF(R5>0, ((G5+M5)/R5)/(1-Inputs!B2), 0) -> 244.34389
A6: Sam (Apprentice) | B6: Hourly | C6: 40 | E6: 22 | F6: =IF(B6="Salaried",D6/52,E6*C6) -> 880 | G6: =IF(C6>0,F6/C6,0) -> 22 | H6: 85 | I6: 18 | J6: =H6*I6 -> 1530 | K6: =C6-I6 -> 22 | L6: =K6*G6 -> 484 | M6: =IF(SUM(C:C)>0,(Inputs!B1*12/52)/SUM(C:C),0) -> 28.846154 | N6: =C6*M6 -> 1153.8462 | O6: =F6+N6 -> 2033.8462 | P6: =J6-O6 -> -503.84615 | Q6: =IF(J6>0,P6/J6,0) -> -0.32931121 | R6: =IF(C6>0,I6/C6,0) -> 0.45 | S6: =H6*C6 -> 3400 | T6: =S6-J6 -> 1870 | U6: =S6-O6 -> 1366.1538 | V6: =IF(S6>0,U6/S6,0) -> 0.40180995 | W6: =IF(R6>0, ((G6+M6)/R6)/(1-Inputs!B2), 0) -> 225.98291
A7: Kelly (Billing/Admin) | B7: Salaried | C7: 40 | D7: 62400 | F7: =IF(B7="Salaried",D7/52,E7*C7) -> 1200 | G7: =IF(C7>0,F7/C7,0) -> 30 | H7: 0 | I7: 0 | J7: =H7*I7 -> 0 | K7: =C7-I7 -> 40 | L7: =K7*G7 -> 1200 | M7: =IF(SUM(C:C)>0,(Inputs!B1*12/52)/SUM(C:C),0) -> 28.846154 | N7: =C7*M7 -> 1153.8462 | O7: =F7+N7 -> 2353.8462 | P7: =J7-O7 -> -2353.8462 | Q7: =IF(J7>0,P7/J7,0) -> 0 | R7: =IF(C7>0,I7/C7,0) -> 0 | S7: =H7*C7 -> 0 | T7: =S7-J7 -> 0 | U7: =S7-O7 -> -2353.8462 | V7: =IF(S7>0,U7/S7,0) -> 0 | W7: =IF(R7>0, ((G7+M7)/R7)/(1-Inputs!B2), 0) -> 0
F8: =IF(B8="Salaried",D8/52,E8*C8) -> 0 | G8: =IF(C8>0,F8/C8,0) -> 0 | J8: =H8*I8 -> 0 | K8: =C8-I8 -> 0 | L8: =K8*G8 -> 0 | M8: =IF(SUM(C:C)>0,(Inputs!B1*12/52)/SUM(C:C),0) -> 28.846154 | N8: =C8*M8 -> 0 | O8: =F8+N8 -> 0 | P8: =J8-O8 -> 0 | Q8: =IF(J8>0,P8/J8,0) -> 0 | R8: =IF(C8>0,I8/C8,0) -> 0 | S8: =H8*C8 -> 0 | T8: =S8-J8 -> 0 | U8: =S8-O8 -> 0 | V8: =IF(S8>0,U8/S8,0) -> 0 | W8: =IF(R8>0, ((G8+M8)/R8)/(1-Inputs!B2), 0) -> 0
F9: =IF(B9="Salaried",D9/52,E9*C9) -> 0 | G9: =IF(C9>0,F9/C9,0) -> 0 | J9: =H9*I9 -> 0 | K9: =C9-I9 -> 0 | L9: =K9*G9 -> 0 | M9: =IF(SUM(C:C)>0,(Inputs!B1*12/52)/SUM(C:C),0) -> 28.846154 | N9: =C9*M9 -> 0 | O9: =F9+N9 -> 0 | P9: =J9-O9 -> 0 | Q9: =IF(J9>0,P9/J9,0) -> 0 | R9: =IF(C9>0,I9/C9,0) -> 0 | S9: =H9*C9 -> 0 | T9: =S9-J9 -> 0 | U9: =S9-O9 -> 0 | V9: =IF(S9>0,U9/S9,0) -> 0 | W9: =IF(R9>0, ((G9+M9)/R9)/(1-Inputs!B2), 0) -> 0
F10: =IF(B10="Salaried",D10/52,E10*C10) -> 0 | G10: =IF(C10>0,F10/C10,0) -> 0 | J10: =H10*I10 -> 0 | K10: =C10-I10 -> 0 | L10: =K10*G10 -> 0 | M10: =IF(SUM(C:C)>0,(Inputs!B1*12/52)/SUM(C:C),0) -> 28.846154 | N10: =C10*M10 -> 0 | O10: =F10+N10 -> 0 | P10: =J10-O10 -> 0 | Q10: =IF(J10>0,P10/J10,0) -> 0 | R10: =IF(C10>0,I10/C10,0) -> 0 | S10: =H10*C10 -> 0 | T10: =S10-J10 -> 0 | U10: =S10-O10 -> 0 | V10: =IF(S10>0,U10/S10,0) -> 0 | W10: =IF(R10>0, ((G10+M10)/R10)/(1-Inputs!B2), 0) -> 0
F11: =IF(B11="Salaried",D11/52,E11*C11) -> 0 | G11: =IF(C11>0,F11/C11,0) -> 0 | J11: =H11*I11 -> 0 | K11: =C11-I11 -> 0 | L11: =K11*G11 -> 0 | M11: =IF(SUM(C:C)>0,(Inputs!B1*12/52)/SUM(C:C),0) -> 28.846154 | N11: =C11*M11 -> 0 | O11: =F11+N11 -> 0 | P11: =J11-O11 -> 0 | Q11: =IF(J11>0,P11/J11,0) -> 0 | R11: =IF(C11>0,I11/C11,0) -> 0 | S11: =H11*C11 -> 0 | T11: =S11-J11 -> 0 | U11: =S11-O11 -> 0 | V11: =IF(S11>0,U11/S11,0) -> 0 | W11: =IF(R11>0, ((G11+M11)/R11)/(1-Inputs!B2), 0) -> 0
F12: =IF(B12="Salaried",D12/52,E12*C12) -> 0 | G12: =IF(C12>0,F12/C12,0) -> 0 | J12: =H12*I12 -> 0 | K12: =C12-I12 -> 0 | L12: =K12*G12 -> 0 | M12: =IF(SUM(C:C)>0,(Inputs!B1*12/52)/SUM(C:C),0) -> 28.846154 | N12: =C12*M12 -> 0 | O12: =F12+N12 -> 0 | P12: =J12-O12 -> 0 | Q12: =IF(J12>0,P12/J12,0) -> 0 | R12: =IF(C12>0,I12/C12,0) -> 0 | S12: =H12*C12 -> 0 | T12: =S12-J12 -> 0 | U12: =S12-O12 -> 0 | V12: =IF(S12>0,U12/S12,0) -> 0 | W12: =IF(R12>0, ((G12+M12)/R12)/(1-Inputs!B2), 0) -> 0
F13: =IF(B13="Salaried",D13/52,E13*C13) -> 0 | G13: =IF(C13>0,F13/C13,0) -> 0 | J13: =H13*I13 -> 0 | K13: =C13-I13 -> 0 | L13: =K13*G13 -> 0 | M13: =IF(SUM(C:C)>0,(Inputs!B1*12/52)/SUM(C:C),0) -> 28.846154 | N13: =C13*M13 -> 0 | O13: =F13+N13 -> 0 | P13: =J13-O13 -> 0 | Q13: =IF(J13>0,P13/J13,0) -> 0 | R13: =IF(C13>0,I13/C13,0) -> 0 | S13: =H13*C13 -> 0 | T13: =S13-J13 -> 0 | U13: =S13-O13 -> 0 | V13: =IF(S13>0,U13/S13,0) -> 0 | W13: =IF(R13>0, ((G13+M13)/R13)/(1-Inputs!B2), 0) -> 0
F14: =IF(B14="Salaried",D14/52,E14*C14) -> 0 | G14: =IF(C14>0,F14/C14,0) -> 0 | J14: =H14*I14 -> 0 | K14: =C14-I14 -> 0 | L14: =K14*G14 -> 0 | M14: =IF(SUM(C:C)>0,(Inputs!B1*12/52)/SUM(C:C),0) -> 28.846154 | N14: =C14*M14 -> 0 | O14: =F14+N14 -> 0 | P14: =J14-O14 -> 0 | Q14: =IF(J14>0,P14/J14,0) -> 0 | R14: =IF(C14>0,I14/C14,0) -> 0 | S14: =H14*C14 -> 0 | T14: =S14-J14 -> 0 | U14: =S14-O14 -> 0 | V14: =IF(S14>0,U14/S14,0) -> 0 | W14: =IF(R14>0, ((G14+M14)/R14)/(1-Inputs!B2), 0) -> 0
F15: =IF(B15="Salaried",D15/52,E15*C15) -> 0 | G15: =IF(C15>0,F15/C15,0) -> 0 | J15: =H15*I15 -> 0 | K15: =C15-I15 -> 0 | L15: =K15*G15 -> 0 | M15: =IF(SUM(C:C)>0,(Inputs!B1*12/52)/SUM(C:C),0) -> 28.846154 | N15: =C15*M15 -> 0 | O15: =F15+N15 -> 0 | P15: =J15-O15 -> 0 | Q15: =IF(J15>0,P15/J15,0) -> 0 | R15: =IF(C15>0,I15/C15,0) -> 0 | S15: =H15*C15 -> 0 | T15: =S15-J15 -> 0 | U15: =S15-O15 -> 0 | V15: =IF(S15>0,U15/S15,0) -> 0 | W15: =IF(R15>0, ((G15+M15)/R15)/(1-Inputs!B2), 0) -> 0
F16: =IF(B16="Salaried",D16/52,E16*C16) -> 0 | G16: =IF(C16>0,F16/C16,0) -> 0 | J16: =H16*I16 -> 0 | K16: =C16-I16 -> 0 | L16: =K16*G16 -> 0 | M16: =IF(SUM(C:C)>0,(Inputs!B1*12/52)/SUM(C:C),0) -> 28.846154 | N16: =C16*M16 -> 0 | O16: =F16+N16 -> 0 | P16: =J16-O16 -> 0 | Q16: =IF(J16>0,P16/J16,0) -> 0 | R16: =IF(C16>0,I16/C16,0) -> 0 | S16: =H16*C16 -> 0 | T16: =S16-J16 -> 0 | U16: =S16-O16 -> 0 | V16: =IF(S16>0,U16/S16,0) -> 0 | W16: =IF(R16>0, ((G16+M16)/R16)/(1-Inputs!B2), 0) -> 0
F17: =IF(B17="Salaried",D17/52,E17*C17) -> 0 | G17: =IF(C17>0,F17/C17,0) -> 0 | J17: =H17*I17 -> 0 | K17: =C17-I17 -> 0 | L17: =K17*G17 -> 0 | M17: =IF(SUM(C:C)>0,(Inputs!B1*12/52)/SUM(C:C),0) -> 28.846154 | N17: =C17*M17 -> 0 | O17: =F17+N17 -> 0 | P17: =J17-O17 -> 0 | Q17: =IF(J17>0,P17/J17,0) -> 0 | R17: =IF(C17>0,I17/C17,0) -> 0 | S17: =H17*C17 -> 0 | T17: =S17-J17 -> 0 | U17: =S17-O17 -> 0 | V17: =IF(S17>0,U17/S17,0) -> 0 | W17: =IF(R17>0, ((G17+M17)/R17)/(1-Inputs!B2), 0) -> 0
F18: =IF(B18="Salaried",D18/52,E18*C18) -> 0 | G18: =IF(C18>0,F18/C18,0) -> 0 | J18: =H18*I18 -> 0 | K18: =C18-I18 -> 0 | L18: =K18*G18 -> 0 | M18: =IF(SUM(C:C)>0,(Inputs!B1*12/52)/SUM(C:C),0) -> 28.846154 | N18: =C18*M18 -> 0 | O18: =F18+N18 -> 0 | P18: =J18-O18 -> 0 | Q18: =IF(J18>0,P18/J18,0) -> 0 | R18: =IF(C18>0,I18/C18,0) -> 0 | S18: =H18*C18 -> 0 | T18: =S18-J18 -> 0 | U18: =S18-O18 -> 0 | V18: =IF(S18>0,U18/S18,0) -> 0 | W18: =IF(R18>0, ((G18+M18)/R18)/(1-Inputs!B2), 0) -> 0
F19: =IF(B19="Salaried",D19/52,E19*C19) -> 0 | G19: =IF(C19>0,F19/C19,0) -> 0 | J19: =H19*I19 -> 0 | K19: =C19-I19 -> 0 | L19: =K19*G19 -> 0 | M19: =IF(SUM(C:C)>0,(Inputs!B1*12/52)/SUM(C:C),0) -> 28.846154 | N19: =C19*M19 -> 0 | O19: =F19+N19 -> 0 | P19: =J19-O19 -> 0 | Q19: =IF(J19>0,P19/J19,0) -> 0 | R19: =IF(C19>0,I19/C19,0) -> 0 | S19: =H19*C19 -> 0 | T19: =S19-J19 -> 0 | U19: =S19-O19 -> 0 | V19: =IF(S19>0,U19/S19,0) -> 0 | W19: =IF(R19>0, ((G19+M19)/R19)/(1-Inputs!B2), 0) -> 0
F20: =IF(B20="Salaried",D20/52,E20*C20) -> 0 | G20: =IF(C20>0,F20/C20,0) -> 0 | J20: =H20*I20 -> 0 | K20: =C20-I20 -> 0 | L20: =K20*G20 -> 0 | M20: =IF(SUM(C:C)>0,(Inputs!B1*12/52)/SUM(C:C),0) -> 28.846154 | N20: =C20*M20 -> 0 | O20: =F20+N20 -> 0 | P20: =J20-O20 -> 0 | Q20: =IF(J20>0,P20/J20,0) -> 0 | R20: =IF(C20>0,I20/C20,0) -> 0 | S20: =H20*C20 -> 0 | T20: =S20-J20 -> 0 | U20: =S20-O20 -> 0 | V20: =IF(S20>0,U20/S20,0) -> 0 | W20: =IF(R20>0, ((G20+M20)/R20)/(1-Inputs!B2), 0) -> 0
F21: =IF(B21="Salaried",D21/52,E21*C21) -> 0 | G21: =IF(C21>0,F21/C21,0) -> 0 | J21: =H21*I21 -> 0 | K21: =C21-I21 -> 0 | L21: =K21*G21 -> 0 | M21: =IF(SUM(C:C)>0,(Inputs!B1*12/52)/SUM(C:C),0) -> 28.846154 | N21: =C21*M21 -> 0 | O21: =F21+N21 -> 0 | P21: =J21-O21 -> 0 | Q21: =IF(J21>0,P21/J21,0) -> 0 | R21: =IF(C21>0,I21/C21,0) -> 0 | S21: =H21*C21 -> 0 | T21: =S21-J21 -> 0 | U21: =S21-O21 -> 0 | V21: =IF(S21>0,U21/S21,0) -> 0 | W21: =IF(R21>0, ((G21+M21)/R21)/(1-Inputs!B2), 0) -> 0
F22: =IF(B22="Salaried",D22/52,E22*C22) -> 0 | G22: =IF(C22>0,F22/C22,0) -> 0 | J22: =H22*I22 -> 0 | K22: =C22-I22 -> 0 | L22: =K22*G22 -> 0 | M22: =IF(SUM(C:C)>0,(Inputs!B1*12/52)/SUM(C:C),0) -> 28.846154 | N22: =C22*M22 -> 0 | O22: =F22+N22 -> 0 | P22: =J22-O22 -> 0 | Q22: =IF(J22>0,P22/J22,0) -> 0 | R22: =IF(C22>0,I22/C22,0) -> 0 | S22: =H22*C22 -> 0 | T22: =S22-J22 -> 0 | U22: =S22-O22 -> 0 | V22: =IF(S22>0,U22/S22,0) -> 0 | W22: =IF(R22>0, ((G22+M22)/R22)/(1-Inputs!B2), 0) -> 0
F23: =IF(B23="Salaried",D23/52,E23*C23) -> 0 | G23: =IF(C23>0,F23/C23,0) -> 0 | J23: =H23*I23 -> 0 | K23: =C23-I23 -> 0 | L23: =K23*G23 -> 0 | M23: =IF(SUM(C:C)>0,(Inputs!B1*12/52)/SUM(C:C),0) -> 28.846154 | N23: =C23*M23 -> 0 | O23: =F23+N23 -> 0 | P23: =J23-O23 -> 0 | Q23: =IF(J23>0,P23/J23,0) -> 0 | R23: =IF(C23>0,I23/C23,0) -> 0 | S23: =H23*C23 -> 0 | T23: =S23-J23 -> 0 | U23: =S23-O23 -> 0 | V23: =IF(S23>0,U23/S23,0) -> 0 | W23: =IF(R23>0, ((G23+M23)/R23)/(1-Inputs!B2), 0) -> 0
F24: =IF(B24="Salaried",D24/52,E24*C24) -> 0 | G24: =IF(C24>0,F24/C24,0) -> 0 | J24: =H24*I24 -> 0 | K24: =C24-I24 -> 0 | L24: =K24*G24 -> 0 | M24: =IF(SUM(C:C)>0,(Inputs!B1*12/52)/SUM(C:C),0) -> 28.846154 | N24: =C24*M24 -> 0 | O24: =F24+N24 -> 0 | P24: =J24-O24 -> 0 | Q24: =IF(J24>0,P24/J24,0) -> 0 | R24: =IF(C24>0,I24/C24,0) -> 0 | S24: =H24*C24 -> 0 | T24: =S24-J24 -> 0 | U24: =S24-O24 -> 0 | V24: =IF(S24>0,U24/S24,0) -> 0 | W24: =IF(R24>0, ((G24+M24)/R24)/(1-Inputs!B2), 0) -> 0
F25: =IF(B25="Salaried",D25/52,E25*C25) -> 0 | G25: =IF(C25>0,F25/C25,0) -> 0 | J25: =H25*I25 -> 0 | K25: =C25-I25 -> 0 | L25: =K25*G25 -> 0 | M25: =IF(SUM(C:C)>0,(Inputs!B1*12/52)/SUM(C:C),0) -> 28.846154 | N25: =C25*M25 -> 0 | O25: =F25+N25 -> 0 | P25: =J25-O25 -> 0 | Q25: =IF(J25>0,P25/J25,0) -> 0 | R25: =IF(C25>0,I25/C25,0) -> 0 | S25: =H25*C25 -> 0 | T25: =S25-J25 -> 0 | U25: =S25-O25 -> 0 | V25: =IF(S25>0,U25/S25,0) -> 0 | W25: =IF(R25>0, ((G25+M25)/R25)/(1-Inputs!B2), 0) -> 0
F26: =IF(B26="Salaried",D26/52,E26*C26) -> 0 | G26: =IF(C26>0,F26/C26,0) -> 0 | J26: =H26*I26 -> 0 | K26: =C26-I26 -> 0 | L26: =K26*G26 -> 0 | M26: =IF(SUM(C:C)>0,(Inputs!B1*12/52)/SUM(C:C),0) -> 28.846154 | N26: =C26*M26 -> 0 | O26: =F26+N26 -> 0 | P26: =J26-O26 -> 0 | Q26: =IF(J26>0,P26/J26,0) -> 0 | R26: =IF(C26>0,I26/C26,0) -> 0 | S26: =H26*C26 -> 0 | T26: =S26-J26 -> 0 | U26: =S26-O26 -> 0 | V26: =IF(S26>0,U26/S26,0) -> 0 | W26: =IF(R26>0, ((G26+M26)/R26)/(1-Inputs!B2), 0) -> 0
F27: =IF(B27="Salaried",D27/52,E27*C27) -> 0 | G27: =IF(C27>0,F27/C27,0) -> 0 | J27: =H27*I27 -> 0 | K27: =C27-I27 -> 0 | L27: =K27*G27 -> 0 | M27: =IF(SUM(C:C)>0,(Inputs!B1*12/52)/SUM(C:C),0) -> 28.846154 | N27: =C27*M27 -> 0 | O27: =F27+N27 -> 0 | P27: =J27-O27 -> 0 | Q27: =IF(J27>0,P27/J27,0) -> 0 | R27: =IF(C27>0,I27/C27,0) -> 0 | S27: =H27*C27 -> 0 | T27: =S27-J27 -> 0 | U27: =S27-O27 -> 0 | V27: =IF(S27>0,U27/S27,0) -> 0 | W27: =IF(R27>0, ((G27+M27)/R27)/(1-Inputs!B2), 0) -> 0
F28: =IF(B28="Salaried",D28/52,E28*C28) -> 0 | G28: =IF(C28>0,F28/C28,0) -> 0 | J28: =H28*I28 -> 0 | K28: =C28-I28 -> 0 | L28: =K28*G28 -> 0 | M28: =IF(SUM(C:C)>0,(Inputs!B1*12/52)/SUM(C:C),0) -> 28.846154 | N28: =C28*M28 -> 0 | O28: =F28+N28 -> 0 | P28: =J28-O28 -> 0 | Q28: =IF(J28>0,P28/J28,0) -> 0 | R28: =IF(C28>0,I28/C28,0) -> 0 | S28: =H28*C28 -> 0 | T28: =S28-J28 -> 0 | U28: =S28-O28 -> 0 | V28: =IF(S28>0,U28/S28,0) -> 0 | W28: =IF(R28>0, ((G28+M28)/R28)/(1-Inputs!B2), 0) -> 0
F29: =IF(B29="Salaried",D29/52,E29*C29) -> 0 | G29: =IF(C29>0,F29/C29,0) -> 0 | J29: =H29*I29 -> 0 | K29: =C29-I29 -> 0 | L29: =K29*G29 -> 0 | M29: =IF(SUM(C:C)>0,(Inputs!B1*12/52)/SUM(C:C),0) -> 28.846154 | N29: =C29*M29 -> 0 | O29: =F29+N29 -> 0 | P29: =J29-O29 -> 0 | Q29: =IF(J29>0,P29/J29,0) -> 0 | R29: =IF(C29>0,I29/C29,0) -> 0 | S29: =H29*C29 -> 0 | T29: =S29-J29 -> 0 | U29: =S29-O29 -> 0 | V29: =IF(S29>0,U29/S29,0) -> 0 | W29: =IF(R29>0, ((G29+M29)/R29)/(1-Inputs!B2), 0) -> 0
F30: =IF(B30="Salaried",D30/52,E30*C30) -> 0 | G30: =IF(C30>0,F30/C30,0) -> 0 | J30: =H30*I30 -> 0 | K30: =C30-I30 -> 0 | L30: =K30*G30 -> 0 | M30: =IF(SUM(C:C)>0,(Inputs!B1*12/52)/SUM(C:C),0) -> 28.846154 | N30: =C30*M30 -> 0 | O30: =F30+N30 -> 0 | P30: =J30-O30 -> 0 | Q30: =IF(J30>0,P30/J30,0) -> 0 | R30: =IF(C30>0,I30/C30,0) -> 0 | S30: =H30*C30 -> 0 | T30: =S30-J30 -> 0 | U30: =S30-O30 -> 0 | V30: =IF(S30>0,U30/S30,0) -> 0 | W30: =IF(R30>0, ((G30+M30)/R30)/(1-Inputs!B2), 0) -> 0
F31: =IF(B31="Salaried",D31/52,E31*C31) -> 0 | G31: =IF(C31>0,F31/C31,0) -> 0 | J31: =H31*I31 -> 0 | K31: =C31-I31 -> 0 | L31: =K31*G31 -> 0 | M31: =IF(SUM(C:C)>0,(Inputs!B1*12/52)/SUM(C:C),0) -> 28.846154 | N31: =C31*M31 -> 0 | O31: =F31+N31 -> 0 | P31: =J31-O31 -> 0 | Q31: =IF(J31>0,P31/J31,0) -> 0 | R31: =IF(C31>0,I31/C31,0) -> 0 | S31: =H31*C31 -> 0 | T31: =S31-J31 -> 0 | U31: =S31-O31 -> 0 | V31: =IF(S31>0,U31/S31,0) -> 0 | W31: =IF(R31>0, ((G31+M31)/R31)/(1-Inputs!B2), 0) -> 0
F32: =IF(B32="Salaried",D32/52,E32*C32) -> 0 | G32: =IF(C32>0,F32/C32,0) -> 0 | J32: =H32*I32 -> 0 | K32: =C32-I32 -> 0 | L32: =K32*G32 -> 0 | M32: =IF(SUM(C:C)>0,(Inputs!B1*12/52)/SUM(C:C),0) -> 28.846154 | N32: =C32*M32 -> 0 | O32: =F32+N32 -> 0 | P32: =J32-O32 -> 0 | Q32: =IF(J32>0,P32/J32,0) -> 0 | R32: =IF(C32>0,I32/C32,0) -> 0 | S32: =H32*C32 -> 0 | T32: =S32-J32 -> 0 | U32: =S32-O32 -> 0 | V32: =IF(S32>0,U32/S32,0) -> 0 | W32: =IF(R32>0, ((G32+M32)/R32)/(1-Inputs!B2), 0) -> 0
F33: =IF(B33="Salaried",D33/52,E33*C33) -> 0 | G33: =IF(C33>0,F33/C33,0) -> 0 | J33: =H33*I33 -> 0 | K33: =C33-I33 -> 0 | L33: =K33*G33 -> 0 | M33: =IF(SUM(C:C)>0,(Inputs!B1*12/52)/SUM(C:C),0) -> 28.846154 | N33: =C33*M33 -> 0 | O33: =F33+N33 -> 0 | P33: =J33-O33 -> 0 | Q33: =IF(J33>0,P33/J33,0) -> 0 | R33: =IF(C33>0,I33/C33,0) -> 0 | S33: =H33*C33 -> 0 | T33: =S33-J33 -> 0 | U33: =S33-O33 -> 0 | V33: =IF(S33>0,U33/S33,0) -> 0 | W33: =IF(R33>0, ((G33+M33)/R33)/(1-Inputs!B2), 0) -> 0
F34: =IF(B34="Salaried",D34/52,E34*C34) -> 0 | G34: =IF(C34>0,F34/C34,0) -> 0 | J34: =H34*I34 -> 0 | K34: =C34-I34 -> 0 | L34: =K34*G34 -> 0 | M34: =IF(SUM(C:C)>0,(Inputs!B1*12/52)/SUM(C:C),0) -> 28.846154 | N34: =C34*M34 -> 0 | O34: =F34+N34 -> 0 | P34: =J34-O34 -> 0 | Q34: =IF(J34>0,P34/J34,0) -> 0 | R34: =IF(C34>0,I34/C34,0) -> 0 | S34: =H34*C34 -> 0 | T34: =S34-J34 -> 0 | U34: =S34-O34 -> 0 | V34: =IF(S34>0,U34/S34,0) -> 0 | W34: =IF(R34>0, ((G34+M34)/R34)/(1-Inputs!B2), 0) -> 0
F35: =IF(B35="Salaried",D35/52,E35*C35) -> 0 | G35: =IF(C35>0,F35/C35,0) -> 0 | J35: =H35*I35 -> 0 | K35: =C35-I35 -> 0 | L35: =K35*G35 -> 0 | M35: =IF(SUM(C:C)>0,(Inputs!B1*12/52)/SUM(C:C),0) -> 28.846154 | N35: =C35*M35 -> 0 | O35: =F35+N35 -> 0 | P35: =J35-O35 -> 0 | Q35: =IF(J35>0,P35/J35,0) -> 0 | R35: =IF(C35>0,I35/C35,0) -> 0 | S35: =H35*C35 -> 0 | T35: =S35-J35 -> 0 | U35: =S35-O35 -> 0 | V35: =IF(S35>0,U35/S35,0) -> 0 | W35: =IF(R35>0, ((G35+M35)/R35)/(1-Inputs!B2), 0) -> 0
F36: =IF(B36="Salaried",D36/52,E36*C36) -> 0 | G36: =IF(C36>0,F36/C36,0) -> 0 | J36: =H36*I36 -> 0 | K36: =C36-I36 -> 0 | L36: =K36*G36 -> 0 | M36: =IF(SUM(C:C)>0,(Inputs!B1*12/52)/SUM(C:C),0) -> 28.846154 | N36: =C36*M36 -> 0 | O36: =F36+N36 -> 0 | P36: =J36-O36 -> 0 | Q36: =IF(J36>0,P36/J36,0) -> 0 | R36: =IF(C36>0,I36/C36,0) -> 0 | S36: =H36*C36 -> 0 | T36: =S36-J36 -> 0 | U36: =S36-O36 -> 0 | V36: =IF(S36>0,U36/S36,0) -> 0 | W36: =IF(R36>0, ((G36+M36)/R36)/(1-Inputs!B2), 0) -> 0
F37: =IF(B37="Salaried",D37/52,E37*C37) -> 0 | G37: =IF(C37>0,F37/C37,0) -> 0 | J37: =H37*I37 -> 0 | K37: =C37-I37 -> 0 | L37: =K37*G37 -> 0 | M37: =IF(SUM(C:C)>0,(Inputs!B1*12/52)/SUM(C:C),0) -> 28.846154 | N37: =C37*M37 -> 0 | O37: =F37+N37 -> 0 | P37: =J37-O37 -> 0 | Q37: =IF(J37>0,P37/J37,0) -> 0 | R37: =IF(C37>0,I37/C37,0) -> 0 | S37: =H37*C37 -> 0 | T37: =S37-J37 -> 0 | U37: =S37-O37 -> 0 | V37: =IF(S37>0,U37/S37,0) -> 0 | W37: =IF(R37>0, ((G37+M37)/R37)/(1-Inputs!B2), 0) -> 0
F38: =IF(B38="Salaried",D38/52,E38*C38) -> 0 | G38: =IF(C38>0,F38/C38,0) -> 0 | J38: =H38*I38 -> 0 | K38: =C38-I38 -> 0 | L38: =K38*G38 -> 0 | M38: =IF(SUM(C:C)>0,(Inputs!B1*12/52)/SUM(C:C),0) -> 28.846154 | N38: =C38*M38 -> 0 | O38: =F38+N38 -> 0 | P38: =J38-O38 -> 0 | Q38: =IF(J38>0,P38/J38,0) -> 0 | R38: =IF(C38>0,I38/C38,0) -> 0 | S38: =H38*C38 -> 0 | T38: =S38-J38 -> 0 | U38: =S38-O38 -> 0 | V38: =IF(S38>0,U38/S38,0) -> 0 | W38: =IF(R38>0, ((G38+M38)/R38)/(1-Inputs!B2), 0) -> 0
F39: =IF(B39="Salaried",D39/52,E39*C39) -> 0 | G39: =IF(C39>0,F39/C39,0) -> 0 | J39: =H39*I39 -> 0 | K39: =C39-I39 -> 0 | L39: =K39*G39 -> 0 | M39: =IF(SUM(C:C)>0,(Inputs!B1*12/52)/SUM(C:C),0) -> 28.846154 | N39: =C39*M39 -> 0 | O39: =F39+N39 -> 0 | P39: =J39-O39 -> 0 | Q39: =IF(J39>0,P39/J39,0) -> 0 | R39: =IF(C39>0,I39/C39,0) -> 0 | S39: =H39*C39 -> 0 | T39: =S39-J39 -> 0 | U39: =S39-O39 -> 0 | V39: =IF(S39>0,U39/S39,0) -> 0 | W39: =IF(R39>0, ((G39+M39)/R39)/(1-Inputs!B2), 0) -> 0
F40: =IF(B40="Salaried",D40/52,E40*C40) -> 0 | G40: =IF(C40>0,F40/C40,0) -> 0 | J40: =H40*I40 -> 0 | K40: =C40-I40 -> 0 | L40: =K40*G40 -> 0 | M40: =IF(SUM(C:C)>0,(Inputs!B1*12/52)/SUM(C:C),0) -> 28.846154 | N40: =C40*M40 -> 0 | O40: =F40+N40 -> 0 | P40: =J40-O40 -> 0 | Q40: =IF(J40>0,P40/J40,0) -> 0 | R40: =IF(C40>0,I40/C40,0) -> 0 | S40: =H40*C40 -> 0 | T40: =S40-J40 -> 0 | U40: =S40-O40 -> 0 | V40: =IF(S40>0,U40/S40,0) -> 0 | W40: =IF(R40>0, ((G40+M40)/R40)/(1-Inputs!B2), 0) -> 0
...

Sheet Scenarios
A1: Resource Name | B1: Bill Rate | C1: Paid Hours | D1: Cost/hr | E1: Overhead/hr | F1: Total Cost/Week | G1: Billed Hours | H1: Revenue | I1: Profit | J1: Gross Margin %
A2: Austin (Tech I) | B2: {=IFERROR(INDEX(Resources!H:H, MATCH(A2, Resources!A:A, 0)),0)} -> 125 | C2: {=IFERROR(INDEX(Resources!C:C, MATCH(A2, Resources!A:A, 0)),0)} -> 40 | D2: {=IFERROR(INDEX(Resources!G:G, MATCH(A2, Resources!A:A, 0)),0)} -> 35 | E2: {=IFERROR(INDEX(Resources!M:M, MATCH(A2, Resources!A:A, 0)),0)} -> 28.846154 | F2: {=IFERROR(INDEX(Resources!O:O, MATCH(A2, Resources!A:A, 0)),0)} -> 2553.8462 | G2: 10 | H2: =B2*G2 -> 1250 | I2: =H2-F2 -> -1303.8462 | J2: =IF(H2>0,I2/H2,0) -> -1.0430769
B3: {=IFERROR(INDEX(Resources!H:H, MATCH(A3, Resources!A:A, 0)),0)} -> 0 | C3: {=IFERROR(INDEX(Resources!C:C, MATCH(A3, Resources!A:A, 0)),0)} -> 0 | D3: {=IFERROR(INDEX(Resources!G:G, MATCH(A3, Resources!A:A, 0)),0)} -> 0 | E3: {=IFERROR(INDEX(Resources!M:M, MATCH(A3, Resources!A:A, 0)),0)} -> 0 | F3: {=IFERROR(INDEX(Resources!O:O, MATCH(A3, Resources!A:A, 0)),0)} -> 0 | G3: 20 | H3: =B3*G3 -> 0 | I3: =H3-F3 -> 0 | J3: =IF(H3>0,I3/H3,0) -> 0
B4: {=IFERROR(INDEX(Resources!H:H, MATCH(A4, Resources!A:A, 0)),0)} -> 0 | C4: {=IFERROR(INDEX(Resources!C:C, MATCH(A4, Resources!A:A, 0)),0)} -> 0 | D4: {=IFERROR(INDEX(Resources!G:G, MATCH(A4, Resources!A:A, 0)),0)} -> 0 | E4: {=IFERROR(INDEX(Resources!M:M, MATCH(A4, Resources!A:A, 0)),0)} -> 0 | F4: {=IFERROR(INDEX(Resources!O:O, MATCH(A4, Resources!A:A, 0)),0)} -> 0 | G4: 30 | H4: =B4*G4 -> 0 | I4: =H4-F4 -> 0 | J4: =IF(H4>0,I4/H4,0) -> 0
B5: {=IFERROR(INDEX(Resources!H:H, MATCH(A5, Resources!A:A, 0)),0)} -> 0 | C5: {=IFERROR(INDEX(Resources!C:C, MATCH(A5, Resources!A:A, 0)),0)} -> 0 | D5: {=IFERROR(INDEX(Resources!G:G, MATCH(A5, Resources!A:A, 0)),0)} -> 0 | E5: {=IFERROR(INDEX(Resources!M:M, MATCH(A5, Resources!A:A, 0)),0)} -> 0 | F5: {=IFERROR(INDEX(Resources!O:O, MATCH(A5, Resources!A:A, 0)),0)} -> 0 | G5: 40 | H5: =B5*G5 -> 0 | I5: =H5-F5 -> 0 | J5: =IF(H5>0,I5/H5,0) -> 0

Sheet Team Summary
A1: Metric | B1: Value
A2: Total Paid Hours/Week | B2: =SUM(Resources!C:C) -> 240
A3: Total Billed Hours/Week | B3: =SUM(Resources!I:I) -> 133.5
A4: Team Utilization % | B4: =IF(B2>0,B2/A2,0) -> #VALUE!
A5: Total Revenue (This Week) | B5: =SUM(Resources!J:J) -> 18477.5
A6: Total Weekly Cost (Labor + Overhead) | B6: =SUM(Resources!O:O) -> 16423.077
A7: Total Profit (This Week) | B7: =D2-E2 -> 0
A8: Gross Margin % | B8: =IF(D2>0,F2/D2,0) -> 0
A9: Potential Revenue @100% | B9: =SUM(Resources!S:S) -> 26200
A10: Revenue Lost from Idle | B10: =H2-D2 -> 0
A11: Profit @100% | B11: =SUM(Resources!U:U) -> 9776.9231

Sheet JR Example
A1: Name | B1: Paid Hours (day) | C1: Billed Hours (day) | D1: Bill Rate ($/hr) | E1: Hourly Cost ($) | F1: Overhead/hr ($) | G1: Daily Revenue | H1: Daily Cost (Labor+OH) | I1: Daily Profit | J1: Margin %
A2: Austin | B2: 8 | C2: 5.5 | D2: 125 | E2: 35 | F2: =IF(SUM(Resources!C:C)>0,(Inputs!B1*12/260)/SUM(Resources!C:C),5) -> 5.7692308 | G2: =C2*D2 -> 687.5 | H2: =(B2*E2)+(B2*F2) -> 326.15385 | I2: =G2-H2 -> 361.34615 | J2: =IF(G2>0,I2/G2,0) -> 0.52559441
